<?xml version="1.0"?>
<robot name="C:/Users/WELCOME/OneDrive/Desktop/zeuron.ai/mobile_robot.urdf" xmlns:xacro="http://ros.org/wiki/xacro">
  <link name="base_link">
  </link>
  <joint name="rotational motor" type="continuous">
    <parent link="base_link"/>
    <child link="solid(1)"/>
    <axis xyz="1 0 0"/>
    <limit effort="10" velocity="10"/>
    <origin xyz="1 -13.5 3.8" rpy="1.57 0 0"/>
  </joint>
  <link name="solid(1)">
    <visual>
      <origin xyz="0 -0.300239 0.299761" rpy="0 0 0"/>
      <geometry>
        <cylinder radius="3.5" length="1.3"/>
      </geometry>
    </visual>
    <collision>
      <origin xyz="0 -0.300239 0.299761" rpy="0 0 0"/>
      <geometry>
        <cylinder radius="3.5" length="1.3"/>
      </geometry>
    </collision>
  </link>
  <joint name="rotational motor" type="continuous">
    <parent link="base_link"/>
    <child link="solid"/>
    <axis xyz="1 0 0"/>
    <limit effort="10" velocity="10"/>
    <origin xyz="1 2.199761 3.799761" rpy="1.57 0 0"/>
  </joint>
  <link name="solid">
    <visual>
      <geometry>
        <cylinder radius="3.5" length="1.3"/>
      </geometry>
    </visual>
    <collision>
      <geometry>
        <cylinder radius="3.5" length="1.3"/>
      </geometry>
    </collision>
  </link>
  <link name="Sharp's IR sensor GP2D120(1)">
    <visual>
      <origin xyz="-0.0052 -0.0102 0" rpy="0 0 0"/>
      <geometry>
        <box size="0.01 0.03 0.0087"/>
      </geometry>
    </visual>
    <collision>
      <origin xyz="-0.0052 -0.0102 0" rpy="0 0 0"/>
      <geometry>
        <box size="0.01 0.03 0.0087"/>
      </geometry>
    </collision>
    <visual>
      <origin xyz="-0.0109 -0.0102 0" rpy="0 0 0"/>
      <geometry>
        <box size="0.0094 0.03 0.0131"/>
      </geometry>
    </visual>
    <collision>
      <origin xyz="-0.0109 -0.0102 0" rpy="0 0 0"/>
      <geometry>
        <box size="0.0094 0.03 0.0131"/>
      </geometry>
    </collision>
    <visual>
      <origin xyz="-0.0144 -0.0102 0" rpy="0 0 0"/>
      <geometry>
        <box size="0.0023 0.0445 0.0077"/>
      </geometry>
    </visual>
    <collision>
      <origin xyz="-0.0144 -0.0102 0" rpy="0 0 0"/>
      <geometry>
        <box size="0.0023 0.0445 0.0077"/>
      </geometry>
    </collision>
  </link>
  <joint name="base_link_Sharp's IR sensor GP2D120(1)_joint" type="fixed">
    <parent link="base_link"/>
    <child link="Sharp's IR sensor GP2D120(1)"/>
    <origin xyz="16 -11 1" rpy="3.14 0 0"/>
  </joint>
  <link name="Sharp's IR sensor GP2D120">
    <visual>
      <origin xyz="-0.0052 -0.0102 0" rpy="0 0 0"/>
      <geometry>
        <box size="0.01 0.03 0.0087"/>
      </geometry>
    </visual>
    <collision>
      <origin xyz="-0.0052 -0.0102 0" rpy="0 0 0"/>
      <geometry>
        <box size="0.01 0.03 0.0087"/>
      </geometry>
    </collision>
    <visual>
      <origin xyz="-0.0109 -0.0102 0" rpy="0 0 0"/>
      <geometry>
        <box size="0.0094 0.03 0.0131"/>
      </geometry>
    </visual>
    <collision>
      <origin xyz="-0.0109 -0.0102 0" rpy="0 0 0"/>
      <geometry>
        <box size="0.0094 0.03 0.0131"/>
      </geometry>
    </collision>
    <visual>
      <origin xyz="-0.0144 -0.0102 0" rpy="0 0 0"/>
      <geometry>
        <box size="0.0023 0.0445 0.0077"/>
      </geometry>
    </visual>
    <collision>
      <origin xyz="-0.0144 -0.0102 0" rpy="0 0 0"/>
      <geometry>
        <box size="0.0023 0.0445 0.0077"/>
      </geometry>
    </collision>
  </link>
  <joint name="base_link_Sharp's IR sensor GP2D120_joint" type="fixed">
    <parent link="base_link"/>
    <child link="Sharp's IR sensor GP2D120"/>
    <origin xyz="16 -5 1" rpy="3.14 0 0"/>
  </joint>
</robot>
